<?xml version="1.0" ?>
<robot name="">
	<link name="mount_base_link">
		<inertial>
			<origin rpy="0.00000 -0.00000 0.00000" xyz="0.00000 0.00000 0.00000"/>
			<mass value="0.00000"/>
			<inertia ixx="0.00000" ixy="0" ixz="0" iyy="0.00000" iyz="0" izz="0.00000"/>
		</inertial>
	</link>
	<link name="link_x">
		<inertial>
			<origin rpy="0.00000 -0.00000 0.00000" xyz="0.00000 0.00000 0.00000"/>
			<mass value="0.00000"/>
			<inertia ixx="0.00000" ixy="0" ixz="0" iyy="0.00000" iyz="0" izz="0.00000"/>
		</inertial>
	</link>
	<link name="link_y">
		<inertial>
			<origin rpy="0.00000 -0.00000 0.00000" xyz="0.00000 0.00000 0.00000"/>
			<mass value="0.00000"/>
			<inertia ixx="0.00000" ixy="0" ixz="0" iyy="0.00000" iyz="0" izz="0.00000"/>
		</inertial>
	</link>
	<link name="link_z">
		<inertial>
			<origin rpy="0.00000 -0.00000 0.00000" xyz="0.00000 0.00000 0.00000"/>
			<mass value="0.00000"/>
			<inertia ixx="0.00000" ixy="0" ixz="0" iyy="0.00000" iyz="0" izz="0.00000"/>
		</inertial>
	</link>
	<link name="mount_link">
		<inertial>
			<origin rpy="0.00000 -0.00000 0.00000" xyz="0.00000 0.00000 0.00000"/>
			<mass value="1.20000"/>
			<inertia ixx="0.00000" ixy="0" ixz="0" iyy="0.00000" iyz="0" izz="0.00000"/>
		</inertial>
	</link>
	<link name="base_link">
		<inertial>
			<origin rpy="0.00000 -0.00000 0.00000" xyz="0.00000 0.00000 0.00000"/>
			<mass value="1.00000"/>
			<inertia ixx="0.00000" ixy="0" ixz="0" iyy="0.00000" iyz="0" izz="0.00000"/>
		</inertial>
		<visual>
			<origin rpy="0.00000 -0.00000 0.00000" xyz="0.00000 0.00000 0.01000"/>
			<geometry>
				<box size="0.00100 0.00100 0.00100"/>
			</geometry>
			<material name="mat_-1_0">
				<color rgba="1.00000 1.00000 1.00000 1.00000" />
			</material>
		</visual>
		<collision>
			<origin rpy="0.00000 -0.00000 0.00000" xyz="0.00000 0.00000 0.01000"/>
			<geometry>
				<box size="0.00100 0.00100 0.00100"/>
			</geometry>
		</collision>
	</link>
	<link name="hand_base_link">
		<inertial>
			<origin rpy="0.00000 -0.00000 0.00000" xyz="0.00000 0.00000 0.00000"/>
			<mass value="1.00000"/>
			<inertia ixx="0.00000" ixy="0" ixz="0" iyy="0.00000" iyz="0" izz="0.00000"/>
		</inertial>
	</link>
	<link name="bh_base_link">
		<inertial>
			<origin rpy="0.00000 -0.00000 0.00000" xyz="0.00000 0.00000 0.00000"/>
			<mass value="3.00000"/>
			<inertia ixx="0.00334" ixy="0" ixz="0" iyy="0.00334" iyz="0" izz="0.00451"/>
		</inertial>
		<visual>
			<origin rpy="0.00000 -0.00000 0.00000" xyz="0.00000 0.00000 0.00000"/>
			<geometry>
				<mesh filename="assets//../assets/robot_hands/barrett/stl/palm_282.stl" scale="1.00000 1.00000 1.00000"/>
			</geometry>
			<material name="mat_1_0">
				<color rgba="0.75000 0.75000 0.75000 1.00000" />
			</material>
		</visual>
		<collision>
			<origin rpy="0.00000 -0.00000 0.00000" xyz="0.00000 0.00000 0.00000"/>
			<geometry>
				<mesh filename="assets//../assets/robot_hands/barrett/stl/palm_282.stl" scale="1.00000 1.00000 1.00000"/>
			</geometry>
		</collision>
	</link>
	<link name="bh_finger_31_link">
		<inertial>
			<origin rpy="0.00000 -0.00000 0.00000" xyz="-0.04600 0.00000 0.00000"/>
			<mass value="0.10000"/>
			<inertia ixx="0.00000" ixy="0" ixz="0" iyy="0.00000" iyz="0" izz="0.00000"/>
		</inertial>
		<visual>
			<origin rpy="0.00000 -0.00000 0.00000" xyz="-0.04000 0.00000 0.00000"/>
			<geometry>
				<mesh filename="assets//../assets/robot_hands/barrett/stl/knuckle_fixed.stl" scale="1.00000 1.00000 1.00000"/>
			</geometry>
			<material name="mat_2_0">
				<color rgba="1.00000 1.00000 1.00000 1.00000" />
			</material>
		</visual>
	</link>
	<link name="bh_finger_32_link">
		<inertial>
			<origin rpy="0.00000 -0.00000 0.00000" xyz="0.00000 0.00000 0.00000"/>
			<mass value="0.10000"/>
			<inertia ixx="0.00002" ixy="0" ixz="0" iyy="0.00009" iyz="0" izz="0.00009"/>
		</inertial>
		<visual>
			<origin rpy="0.00000 -0.00000 0.00000" xyz="0.00000 0.00000 0.00000"/>
			<geometry>
				<mesh filename="assets//../assets/robot_hands/barrett/stl/finger.stl" scale="1.00000 1.00000 1.00000"/>
			</geometry>
			<material name="mat_3_0">
				<color rgba="1.00000 1.00000 1.00000 1.00000" />
			</material>
		</visual>
		<collision>
			<origin rpy="0.00000 -0.00000 0.00000" xyz="0.00000 0.00000 0.00000"/>
			<geometry>
				<mesh filename="assets//../assets/robot_hands/barrett/stl/finger.stl" scale="1.00000 1.00000 1.00000"/>
			</geometry>
		</collision>
	</link>
	<link name="bh_finger_33_link">
		<inertial>
			<origin rpy="0.00000 -0.00000 0.00000" xyz="0.00000 0.00000 0.00000"/>
			<mass value="0.10000"/>
			<inertia ixx="0.00003" ixy="0" ixz="0" iyy="0.00004" iyz="0" izz="0.00006"/>
		</inertial>
		<visual>
			<origin rpy="0.00000 -0.00000 0.00000" xyz="0.00000 0.00000 0.00000"/>
			<geometry>
				<mesh filename="assets//../assets/robot_hands/barrett/stl/finger_tip.stl" scale="1.00000 1.00000 1.00000"/>
			</geometry>
			<material name="mat_4_0">
				<color rgba="1.00000 1.00000 1.00000 1.00000" />
			</material>
		</visual>
		<collision>
			<origin rpy="0.00000 -0.00000 0.00000" xyz="0.00000 0.00000 0.00000"/>
			<geometry>
				<mesh filename="assets//../assets/robot_hands/barrett/stl/finger_tip.stl" scale="1.00000 1.00000 1.00000"/>
			</geometry>
		</collision>
	</link>
	<link name="bh_finger_3_tip_link">
		<inertial>
			<origin rpy="0.00000 -0.00000 0.00000" xyz="0.00000 0.00000 0.00000"/>
			<mass value="1.00000"/>
			<inertia ixx="0.00000" ixy="0" ixz="0" iyy="0.00000" iyz="0" izz="0.00000"/>
		</inertial>
	</link>
	<link name="bh_finger_11_link">
		<inertial>
			<origin rpy="0.00000 -0.00000 0.00000" xyz="-0.04600 0.00000 0.00000"/>
			<mass value="0.10000"/>
			<inertia ixx="0.00000" ixy="0" ixz="0" iyy="0.00000" iyz="0" izz="0.00000"/>
		</inertial>
		<visual>
			<origin rpy="0.00000 -0.00000 0.00000" xyz="0.00000 0.00000 0.00000"/>
			<geometry>
				<mesh filename="assets//../assets/robot_hands/barrett/stl/knuckle.stl" scale="1.00000 1.00000 1.00000"/>
			</geometry>
			<material name="mat_6_0">
				<color rgba="1.00000 1.00000 1.00000 1.00000" />
			</material>
		</visual>
	</link>
	<link name="bh_finger_12_link">
		<inertial>
			<origin rpy="0.00000 -0.00000 0.00000" xyz="0.00000 0.00000 0.00000"/>
			<mass value="0.10000"/>
			<inertia ixx="0.00002" ixy="0" ixz="0" iyy="0.00009" iyz="0" izz="0.00009"/>
		</inertial>
		<visual>
			<origin rpy="0.00000 -0.00000 0.00000" xyz="0.00000 0.00000 0.00000"/>
			<geometry>
				<mesh filename="assets//../assets/robot_hands/barrett/stl/finger.stl" scale="1.00000 1.00000 1.00000"/>
			</geometry>
			<material name="mat_7_0">
				<color rgba="1.00000 1.00000 1.00000 1.00000" />
			</material>
		</visual>
		<collision>
			<origin rpy="0.00000 -0.00000 0.00000" xyz="0.00000 0.00000 0.00000"/>
			<geometry>
				<mesh filename="assets//../assets/robot_hands/barrett/stl/finger.stl" scale="1.00000 1.00000 1.00000"/>
			</geometry>
		</collision>
	</link>
	<link name="bh_finger_13_link">
		<inertial>
			<origin rpy="0.00000 -0.00000 0.00000" xyz="0.00000 0.00000 0.00000"/>
			<mass value="0.10000"/>
			<inertia ixx="0.00003" ixy="0" ixz="0" iyy="0.00004" iyz="0" izz="0.00006"/>
		</inertial>
		<visual>
			<origin rpy="0.00000 -0.00000 0.00000" xyz="0.00000 0.00000 0.00000"/>
			<geometry>
				<mesh filename="assets//../assets/robot_hands/barrett/stl/finger_tip.stl" scale="1.00000 1.00000 1.00000"/>
			</geometry>
			<material name="mat_8_0">
				<color rgba="1.00000 1.00000 1.00000 1.00000" />
			</material>
		</visual>
		<collision>
			<origin rpy="0.00000 -0.00000 0.00000" xyz="0.00000 0.00000 0.00000"/>
			<geometry>
				<mesh filename="assets//../assets/robot_hands/barrett/stl/finger_tip.stl" scale="1.00000 1.00000 1.00000"/>
			</geometry>
		</collision>
	</link>
	<link name="bh_finger_1_tip_link">
		<inertial>
			<origin rpy="0.00000 -0.00000 0.00000" xyz="0.00000 0.00000 0.00000"/>
			<mass value="1.00000"/>
			<inertia ixx="0.00000" ixy="0" ixz="0" iyy="0.00000" iyz="0" izz="0.00000"/>
		</inertial>
	</link>
	<link name="bh_finger_21_link">
		<inertial>
			<origin rpy="0.00000 -0.00000 0.00000" xyz="-0.04600 0.00000 0.00000"/>
			<mass value="0.10000"/>
			<inertia ixx="0.00000" ixy="0" ixz="0" iyy="0.00000" iyz="0" izz="0.00000"/>
		</inertial>
		<visual>
			<origin rpy="0.00000 -0.00000 0.00000" xyz="0.00000 0.00000 0.00000"/>
			<geometry>
				<mesh filename="assets//../assets/robot_hands/barrett/stl/knuckle.stl" scale="1.00000 1.00000 1.00000"/>
			</geometry>
			<material name="mat_10_0">
				<color rgba="1.00000 1.00000 1.00000 1.00000" />
			</material>
		</visual>
	</link>
	<link name="bh_finger_22_link">
		<inertial>
			<origin rpy="0.00000 -0.00000 0.00000" xyz="0.00000 0.00000 0.00000"/>
			<mass value="0.10000"/>
			<inertia ixx="0.00002" ixy="0" ixz="0" iyy="0.00009" iyz="0" izz="0.00009"/>
		</inertial>
		<visual>
			<origin rpy="0.00000 -0.00000 0.00000" xyz="0.00000 0.00000 0.00000"/>
			<geometry>
				<mesh filename="assets//../assets/robot_hands/barrett/stl/finger.stl" scale="1.00000 1.00000 1.00000"/>
			</geometry>
			<material name="mat_11_0">
				<color rgba="1.00000 1.00000 1.00000 1.00000" />
			</material>
		</visual>
		<collision>
			<origin rpy="0.00000 -0.00000 0.00000" xyz="0.00000 0.00000 0.00000"/>
			<geometry>
				<mesh filename="assets//../assets/robot_hands/barrett/stl/finger.stl" scale="1.00000 1.00000 1.00000"/>
			</geometry>
		</collision>
	</link>
	<link name="bh_finger_23_link">
		<inertial>
			<origin rpy="0.00000 -0.00000 0.00000" xyz="0.00000 0.00000 0.00000"/>
			<mass value="0.10000"/>
			<inertia ixx="0.00003" ixy="0" ixz="0" iyy="0.00004" iyz="0" izz="0.00006"/>
		</inertial>
		<visual>
			<origin rpy="0.00000 -0.00000 0.00000" xyz="0.00000 0.00000 0.00000"/>
			<geometry>
				<mesh filename="assets//../assets/robot_hands/barrett/stl/finger_tip.stl" scale="1.00000 1.00000 1.00000"/>
			</geometry>
			<material name="mat_12_0">
				<color rgba="1.00000 1.00000 1.00000 1.00000" />
			</material>
		</visual>
		<collision>
			<origin rpy="0.00000 -0.00000 0.00000" xyz="0.00000 0.00000 0.00000"/>
			<geometry>
				<mesh filename="assets//../assets/robot_hands/barrett/stl/finger_tip.stl" scale="1.00000 1.00000 1.00000"/>
			</geometry>
		</collision>
	</link>
	<link name="bh_finger_2_tip_link">
		<inertial>
			<origin rpy="0.00000 -0.00000 0.00000" xyz="0.00000 0.00000 0.00000"/>
			<mass value="1.00000"/>
			<inertia ixx="0.00000" ixy="0" ixz="0" iyy="0.00000" iyz="0" izz="0.00000"/>
		</inertial>
	</link>
	<link name="bh_palm_link">
		<inertial>
			<origin rpy="0.00000 -0.00000 0.00000" xyz="0.00000 0.00000 0.00000"/>
			<mass value="1.00000"/>
			<inertia ixx="0.00000" ixy="0" ixz="0" iyy="0.00000" iyz="0" izz="0.00000"/>
		</inertial>
	</link>
	<joint name="joint_x" type="prismatic">
		<parent link="mount_base_link"/>
		<child link="link_x"/>
		<limit effort="1000.0" lower="-1000.00000" upper="1000.00000" velocity="10"/>
		<dynamics damping="1.0" friction="0.0001"/>
		<origin rpy="0.00000 -0.00000 0.00000" xyz="0.00000 0.00000 0.00000"/>
		<axis xyz="1.00000 0.00000 0.00000"/>
	</joint>
	<joint name="joint_y" type="prismatic">
		<parent link="link_x"/>
		<child link="link_y"/>
		<limit effort="1000.0" lower="-1000.00000" upper="1000.00000" velocity="10"/>
		<dynamics damping="1.0" friction="0.0001"/>
		<origin rpy="0.00000 -0.00000 0.00000" xyz="0.00000 0.00000 0.00000"/>
		<axis xyz="0.00000 1.00000 0.00000"/>
	</joint>
	<joint name="joint_z" type="prismatic">
		<parent link="link_y"/>
		<child link="link_z"/>
		<limit effort="1000.0" lower="-1000.00000" upper="1000.00000" velocity="10"/>
		<dynamics damping="1.0" friction="0.0001"/>
		<origin rpy="0.00000 -0.00000 0.00000" xyz="0.00000 0.00000 0.00000"/>
		<axis xyz="0.00000 0.00000 1.00000"/>
	</joint>
	<joint name="joint_revolute" type="revolute">
		<parent link="link_z"/>
		<child link="mount_link"/>
		<limit effort="1000.0" lower="-100.00000" upper="100.00000" velocity="10"/>
		<dynamics damping="1.0" friction="0.0001"/>
		<origin rpy="0.00000 -0.00000 0.00000" xyz="0.00000 0.00000 0.00000"/>
		<axis xyz="1.00000 0.00000 0.00000"/>
	</joint>
	<joint name="joint_mount_gripper" type="fixed">
		<parent link="mount_link"/>
		<child link="base_link"/>
		<limit effort="1000.0" lower="0.00000" upper="-1.00000" velocity="10"/>
		<dynamics damping="1.0" friction="0.0001"/>
		<origin rpy="0.00000 -0.00000 0.00000" xyz="0.00000 0.00000 -0.06500"/>
		<axis xyz="0.00000 0.00000 1.00000"/>
	</joint>
	<joint name="hand_joint" type="fixed">
		<parent link="base_link"/>
		<child link="hand_base_link"/>
		<limit effort="1000.0" lower="0.00000" upper="-1.00000" velocity="10"/>
		<dynamics damping="1.0" friction="0.0001"/>
		<origin rpy="0.00000 -0.00000 0.00000" xyz="0.00000 0.00000 0.00000"/>
		<axis xyz="0.00000 0.00000 0.00000"/>
	</joint>
	<joint name="bh_base_joint" type="fixed">
		<parent link="hand_base_link"/>
		<child link="bh_base_link"/>
		<limit effort="1000.0" lower="0.00000" upper="-1.00000" velocity="10"/>
		<dynamics damping="1.0" friction="0.0001"/>
		<origin rpy="0.00000 -0.00000 0.00000" xyz="0.00000 0.00000 0.00000"/>
		<axis xyz="0.00000 0.00000 0.00000"/>
	</joint>
	<joint name="bh_j31_joint" type="fixed">
		<parent link="bh_base_link"/>
		<child link="bh_finger_31_link"/>
		<limit effort="1000.0" lower="0.00000" upper="-1.00000" velocity="10"/>
		<dynamics damping="1.0" friction="0.0001"/>
		<origin rpy="0.00000 0.00000 -1.57080" xyz="0.00000 0.00000 0.02520"/>
		<axis xyz="0.00000 0.00000 0.00000"/>
	</joint>
	<joint name="bh_j32_joint" type="revolute">
		<parent link="bh_finger_31_link"/>
		<child link="bh_finger_32_link"/>
		<limit effort="1000.0" lower="0.00000" upper="2.44000" velocity="10"/>
		<dynamics damping="1.0" friction="0.0001"/>
		<origin rpy="1.57080 -0.00000 0.00000" xyz="-0.05000 0.00000 0.03390"/>
		<axis xyz="0.00000 0.00000 -1.00000"/>
	</joint>
	<joint name="bh_j33_joint" type="revolute">
		<parent link="bh_finger_32_link"/>
		<child link="bh_finger_33_link"/>
		<limit effort="1000.0" lower="0.00000" upper="0.84000" velocity="10"/>
		<dynamics damping="1.0" friction="0.0001"/>
		<origin rpy="0.00000 -0.00000 0.00000" xyz="-0.06994 0.00300 0.00000"/>
		<axis xyz="0.00000 0.00000 -1.00000"/>
	</joint>
	<joint name="bh_j33_tip_joint" type="fixed">
		<parent link="bh_finger_33_link"/>
		<child link="bh_finger_3_tip_link"/>
		<limit effort="1000.0" lower="0.00000" upper="-1.00000" velocity="10"/>
		<dynamics damping="1.0" friction="0.0001"/>
		<origin rpy="0.00000 1.57080 0.80945" xyz="-0.03000 0.03700 0.00000"/>
		<axis xyz="0.00000 0.00000 0.00000"/>
	</joint>
	<joint name="bh_j11_joint" type="revolute">
		<parent link="bh_base_link"/>
		<child link="bh_finger_11_link"/>
		<limit effort="1000.0" lower="0.00000" upper="3.14160" velocity="10"/>
		<dynamics damping="1.0" friction="0.0001"/>
		<origin rpy="0.00000 0.00000 1.57080" xyz="-0.02500 0.00000 0.02520"/>
		<axis xyz="0.00000 0.00000 -1.00000"/>
	</joint>
	<joint name="bh_j12_joint" type="revolute">
		<parent link="bh_finger_11_link"/>
		<child link="bh_finger_12_link"/>
		<limit effort="1000.0" lower="0.00000" upper="2.44000" velocity="10"/>
		<dynamics damping="1.0" friction="0.0001"/>
		<origin rpy="1.57080 -0.00000 0.00000" xyz="-0.05000 0.00000 0.03390"/>
		<axis xyz="0.00000 0.00000 -1.00000"/>
	</joint>
	<joint name="bh_j13_joint" type="revolute">
		<parent link="bh_finger_12_link"/>
		<child link="bh_finger_13_link"/>
		<limit effort="1000.0" lower="0.00000" upper="0.84000" velocity="10"/>
		<dynamics damping="1.0" friction="0.0001"/>
		<origin rpy="0.00000 -0.00000 0.00000" xyz="-0.06994 0.00300 0.00000"/>
		<axis xyz="0.00000 0.00000 -1.00000"/>
	</joint>
	<joint name="bh_j13_tip_joint" type="fixed">
		<parent link="bh_finger_13_link"/>
		<child link="bh_finger_1_tip_link"/>
		<limit effort="1000.0" lower="0.00000" upper="-1.00000" velocity="10"/>
		<dynamics damping="1.0" friction="0.0001"/>
		<origin rpy="0.00000 1.57080 0.80945" xyz="-0.03000 0.03700 0.00000"/>
		<axis xyz="0.00000 0.00000 0.00000"/>
	</joint>
	<joint name="bh_j21_joint" type="revolute">
		<parent link="bh_base_link"/>
		<child link="bh_finger_21_link"/>
		<limit effort="1000.0" lower="0.00000" upper="3.14160" velocity="10"/>
		<dynamics damping="1.0" friction="0.0001"/>
		<origin rpy="0.00000 0.00000 1.57080" xyz="0.02500 0.00000 0.02520"/>
		<axis xyz="0.00000 0.00000 1.00000"/>
	</joint>
	<joint name="bh_j22_joint" type="revolute">
		<parent link="bh_finger_21_link"/>
		<child link="bh_finger_22_link"/>
		<limit effort="1000.0" lower="0.00000" upper="2.44000" velocity="10"/>
		<dynamics damping="1.0" friction="0.0001"/>
		<origin rpy="1.57080 -0.00000 0.00000" xyz="-0.05000 0.00000 0.03390"/>
		<axis xyz="0.00000 0.00000 -1.00000"/>
	</joint>
	<joint name="bh_j23_joint" type="revolute">
		<parent link="bh_finger_22_link"/>
		<child link="bh_finger_23_link"/>
		<limit effort="1000.0" lower="0.00000" upper="0.84000" velocity="10"/>
		<dynamics damping="1.0" friction="0.0001"/>
		<origin rpy="0.00000 -0.00000 0.00000" xyz="-0.06994 0.00300 0.00000"/>
		<axis xyz="0.00000 0.00000 -1.00000"/>
	</joint>
	<joint name="bh_j23_tip_joint" type="fixed">
		<parent link="bh_finger_23_link"/>
		<child link="bh_finger_2_tip_link"/>
		<limit effort="1000.0" lower="0.00000" upper="-1.00000" velocity="10"/>
		<dynamics damping="1.0" friction="0.0001"/>
		<origin rpy="0.00000 1.57080 0.80945" xyz="-0.03000 0.03700 0.00000"/>
		<axis xyz="0.00000 0.00000 0.00000"/>
	</joint>
	<joint name="bh_base_palm_joint" type="fixed">
		<parent link="bh_base_link"/>
		<child link="bh_palm_link"/>
		<limit effort="1000.0" lower="0.00000" upper="-1.00000" velocity="10"/>
		<dynamics damping="1.0" friction="0.0001"/>
		<origin rpy="0.00000 -0.00000 0.00000" xyz="0.00000 0.00000 0.06000"/>
		<axis xyz="0.00000 0.00000 0.00000"/>
	</joint>
</robot>
